<?xml version='1.0'?>
<sdf version='1.4'>
  <model name="morty">
    <static>false</static>

    <link name="body">
      <pose>0 0 0 0 0 0</pose>

      <inertial>
        <pose>-0.010530 0.000000 0.067976 0 0 0</pose>
        <mass>1.0</mass>
        <inertia>
          <ixx>0.000436</ixx>
          <iyy>0.001444</iyy>
          <izz>0.001727</izz>
          <ixz>0.000026</ixz>
          <ixy>-0.000009e-5</ixy>
          <iyz>0.0</iyz>
          </inertia>
      </inertial>

      <collision name="collision">
        <pose>0 0 .07 0 0 0</pose>
        <geometry>
          <box>
            <size>.6 .3 .14</size>
          </box>
        </geometry>
      </collision>

      <visual name="visual">
        <geometry>
          <mesh><uri>model://morty/meshes/body.dae</uri></mesh>
        </geometry>
      </visual>
    </link>

    <!-- Left side. -->
    <link name="rocker_left">
      <pose>.0 .168 .046 0 0 1.571</pose>

      <collision name="collision_rocker_left">
        <pose>0 0 0 0 1.571 0</pose>
        <geometry>
          <cylinder>
            <radius>.05</radius>
            <length>.015</length>
          </cylinder>
        </geometry>
      </collision>

      <visual name="visual_rocker_left">
        <geometry>
          <mesh><uri>model://morty/meshes/rocker_2_left.dae</uri></mesh>
        </geometry>
      </visual>
    </link>

    <link name="bogie_left">
      <pose>.2 .203 -.067 0 0 0</pose>

      <collision name="collision_bogie_left">
        <pose>0 0 0 1.571 0 0</pose>
        <geometry>
          <cylinder>
            <radius>.05</radius>
            <length>.015</length>
          </cylinder>
        </geometry>
      </collision>

      <visual name="visual_bogie_left">
        <geometry>
          <mesh>
            <uri>model://morty/meshes/bogie.dae</uri>
          </mesh>
        </geometry>
      </visual>
    </link>

    <link name="wheel_left_front">
      <pose>.35 .287 -.155 3.141592654 0 0</pose>

      <inertial>
        <pose>-0.000000 0.030998 -0.000003 0 0 0</pose>
        <mass>4.0</mass>
        <inertia>
          <ixx>0.000018</ixx>
          <iyy>0.000031</iyy>
          <izz>0.000018</izz>
          <ixz>-7.4538e-07</ixz>
          <iyz>-0.00014394</iyz>
          </inertia>
      </inertial>

      <collision name="collision_wheel_left_front">
        <pose>0 .03 0 1.570796327 0 0</pose>
        <geometry>
          <cylinder>
            <radius>.11</radius>
            <length>.08</length>
          </cylinder>
        </geometry>
        <surface>
          <friction>
            <ode>
              <mu>1</mu>
              <mu2>1</mu2>
            </ode>
          </friction>
        </surface>
      </collision>
      <collision name="collision_wheel_left_front_axis">
        <pose>0 .11 0 1.570796327 0 0</pose>
        <geometry>
          <cylinder>
            <radius>.01</radius>
            <length>.08</length>
          </cylinder>
        </geometry>
      </collision>

      <visual name="visual_wheel_left_front">
        <geometry>
          <mesh>
            <uri>model://morty/meshes/wheel.dae</uri>
          </mesh>
        </geometry>
      </visual>
    </link>

    <link name="wheel_left_middle">
      <pose>.05 .287 -.155 3.141592654 0 0</pose>

      <inertial>
        <pose>-0.000000 0.030998 -0.000003 0 0 0</pose>
        <mass>4.0</mass>
        <inertia>
          <ixx>0.000018</ixx>
          <iyy>0.000031</iyy>
          <izz>0.000018</izz>
          <ixz>-7.4538e-07</ixz>
          <iyz>-0.00014394</iyz>
          </inertia>
      </inertial>

      <collision name="collision_wheel_left_middle">
        <pose>0 .03 0 1.570796327 0 0</pose>
        <geometry>
          <cylinder>
            <radius>.11</radius>
            <length>.08</length>
          </cylinder>
        </geometry>
        <surface>
          <friction>
            <ode>
              <mu>1</mu>
              <mu2>1</mu2>
            </ode>
          </friction>
        </surface>
      </collision>
      <collision name="collision_wheel_left_middle_axis">
        <pose>0 .11 0 1.570796327 0 0</pose>
        <geometry>
          <cylinder>
            <radius>.01</radius>
            <length>.08</length>
          </cylinder>
        </geometry>
      </collision>

      <visual name="visual_wheel_left_middle">
        <geometry>
          <mesh>
            <uri>model://morty/meshes/wheel.dae</uri>
          </mesh>
        </geometry>
      </visual>
    </link>

    <link name="wheel_left_rear">
      <pose>-.35 .287 -.155 3.141592654 0 0</pose>

      <inertial>
        <pose>-0.000000 0.030998 -0.000003 0 0 0</pose>
        <mass>4.0</mass>
        <inertia>
          <ixx>0.000018</ixx>
          <iyy>0.000031</iyy>
          <izz>0.000018</izz>
          <ixz>-7.4538e-07</ixz>
          <iyz>-0.00014394</iyz>
          </inertia>
      </inertial>

      <collision name="collision_wheel_left_rear">
        <pose>0 .03 0 1.570796327 0 0</pose>
        <geometry>
          <cylinder>
            <radius>.11</radius>
            <length>.08</length>
          </cylinder>
        </geometry>
        <surface>
          <friction>
            <ode>
              <mu>1</mu>
              <mu2>1</mu2>
            </ode>
          </friction>
        </surface>
      </collision>
      <collision name="collision_wheel_left_rear_axis">
        <pose>0 .11 0 1.570796327 0 0</pose>
        <geometry>
          <cylinder>
            <radius>.01</radius>
            <length>.08</length>
          </cylinder>
        </geometry>
      </collision>

      <visual name="visual_wheel_left_rear">
        <geometry>
          <mesh>
            <uri>model://morty/meshes/wheel.dae</uri>
          </mesh>
        </geometry>
      </visual>
    </link>

    <!-- Right side. -->
    <link name="rocker_right">
      <pose>.0 -.168 .046 0 0 1.570796327</pose>

      <collision name="collision_center">
        <pose>0 0 0 0 1.570796327 0</pose>
        <geometry>
          <cylinder>
            <radius>.05</radius>
            <length>.015</length>
          </cylinder>
        </geometry>
      </collision>

      <collision name="collision_pipe_up">
        <pose>0 0 0.05 0 0 0</pose>
        <geometry>
          <cylinder>
            <radius>.01</radius>
            <length>.15</length>
          </cylinder>
        </geometry>
      </collision>

      <visual name="visual_rocker_right">
        <geometry>
          <mesh><uri>model://morty/meshes/rocker_2_right.dae</uri></mesh>
        </geometry>
      </visual>
    </link>

    <link name="bogie_right">
      <pose>.2 -.183 -.067 0 0 0</pose>

      <collision name="collision_bogie_right">
        <pose>0 0 0 1.570796327 0 0</pose>
        <geometry>
          <cylinder>
            <radius>.05</radius>
            <length>.015</length>
          </cylinder>
        </geometry>
      </collision>

      <visual name="visual_bogie_right">
        <geometry>
          <mesh>
            <uri>model://morty/meshes/bogie.dae</uri>
          </mesh>
        </geometry>
      </visual>
    </link>

    <link name="wheel_right_front">
      <pose>.35 -.287 -.155 0 0 0</pose>

      <inertial>
        <pose>-0.000000 0.030998 -0.000003 0 0 0</pose>
        <mass>4.0</mass>
        <inertia>
          <ixx>0.000018</ixx>
          <iyy>0.000031</iyy>
          <izz>0.000018</izz>
          <ixz>-7.4538e-07</ixz>
          <iyz>-0.00014394</iyz>
          </inertia>
      </inertial>

      <collision name="collision_wheel_right_front">
        <pose>0 .03 0 1.570796327 0 0</pose>
        <geometry>
          <cylinder>
            <radius>.11</radius>
            <length>.08</length>
          </cylinder>
        </geometry>
        <surface>
          <friction>
            <ode>
              <mu>1</mu>
              <mu2>1</mu2>
            </ode>
          </friction>
        </surface>
      </collision>
      <collision name="collision_wheel_left_right_axis">
        <pose>0 .11 0 1.570796327 0 0</pose>
        <geometry>
          <cylinder>
            <radius>.01</radius>
            <length>.08</length>
          </cylinder>
        </geometry>
      </collision>

      <visual name="visual_wheel_right_front">
        <geometry>
          <mesh>
            <uri>model://morty/meshes/wheel.dae</uri>
          </mesh>
        </geometry>
      </visual>
    </link>

    <link name="wheel_right_middle">
      <pose>.05 -.287 -.155 0 0 0</pose>

      <inertial>
        <pose>-0.000000 0.030998 -0.000003 0 0 0</pose>
        <mass>4.0</mass>
        <inertia>
          <ixx>0.000018</ixx>
          <iyy>0.000031</iyy>
          <izz>0.000018</izz>
          <ixz>-7.4538e-07</ixz>
          <iyz>-0.00014394</iyz>
          </inertia>
      </inertial>

      <collision name="collision_wheel_right_middle">
        <pose>0 .03 0 1.570796327 0 0</pose>
        <geometry>
          <cylinder>
            <radius>.11</radius>
            <length>.08</length>
          </cylinder>
        </geometry>
        <surface>
          <friction>
            <ode>
              <mu>1</mu>
              <mu2>1</mu2>
            </ode>
          </friction>
        </surface>
      </collision>
      <collision name="collision_wheel_right_middle_axis">
        <pose>0 .11 0 1.570796327 0 0</pose>
        <geometry>
          <cylinder>
            <radius>.01</radius>
            <length>.08</length>
          </cylinder>
        </geometry>
      </collision>

      <visual name="visual_wheel_right_middle">
        <geometry>
          <mesh>
            <uri>model://morty/meshes/wheel.dae</uri>
          </mesh>
        </geometry>
      </visual>
    </link>

    <link name="wheel_right_rear">
      <pose>-.35 -.287 -.155 0 0 0</pose>

      <inertial>
        <pose>-0.000000 0.030998 -0.000003 0 0 0</pose>
        <mass>4.0</mass>
        <inertia>
          <ixx>0.000018</ixx>
          <iyy>0.000031</iyy>
          <izz>0.000018</izz>
          <ixz>-7.4538e-07</ixz>
          <iyz>-0.00014394</iyz>
          </inertia>
      </inertial>

      <collision name="collision_wheel_right_rear">
        <pose>0 .03 0 1.570796327 0 0</pose>
        <geometry>
          <cylinder>
            <radius>.11</radius>
            <length>.08</length>
          </cylinder>
        </geometry>
        <surface>
          <friction>
            <ode>
              <mu>1</mu>
              <mu2>1</mu2>
            </ode>
          </friction>
        </surface>
      </collision>
      <collision name="collision_wheel_right_rear_axis">
        <pose>0 .11 0 1.570796327 0 0</pose>
        <geometry>
          <cylinder>
            <radius>.01</radius>
            <length>.08</length>
          </cylinder>
        </geometry>
      </collision>

      <visual name="visual_wheel_right_rear">
        <geometry>
          <mesh>
            <uri>model://morty/meshes/wheel.dae</uri>
          </mesh>
        </geometry>
      </visual>
    </link>

    <!-- Hebel -->
    <link name="hebel">
      <pose>-0.1 0 0.14 0 0 0</pose>

<!--      <collision name="collision_hebel">
        <geometry>
          <box>
            <size>0.06 0.32 0.03</size>
          </box>
        </geometry>
      </collision>
-->
      <visual name="visual_hebel">
        <geometry>
          <mesh>
            <uri>model://morty/meshes/hebel.dae</uri>
          </mesh>
        </geometry>
      </visual>
    </link>

    <link name="verbinder_left">
      <pose>-0.1 0.152 0.1545 0 0 0</pose>
<!--
      <collision name="collision_verbinder_left">
        <geometry>
          <box>
            <size>0.06 0.03 0.01</size>
          </box>
        </geometry>
      </collision>
-->
      <visual name="visual_verbinder_left">
        <geometry>
          <mesh>
            <uri>model://morty/meshes/verbinder.dae</uri>
          </mesh>
        </geometry>
      </visual>
    </link>

    <link name="verbinder_right">
      <pose>-0.1 -0.152 0.1545 0 0 0</pose>
<!--
      <collision name="collision">
        <pose>0.05 0 0 0 0 0</pose>
        <geometry>
          <box>
            <size>0.13 0.03 0.03</size>
          </box>
        </geometry>
      </collision>
-->
      <visual name="visual">
        <geometry>
          <mesh>
            <uri>model://morty/meshes/verbinder.dae</uri>
          </mesh>
        </geometry>
      </visual>
    </link>

    <!-- Joints -->
    <joint type="revolute" name="left_body_rocker">
      <child>rocker_left</child>
      <parent>body</parent>
      <axis>
        <xyz>0 1 0</xyz>
      </axis>
    </joint>

    <joint type="revolute" name="left_rocker_bogie">
      <pose>0 -0.02 0 0 0 0</pose>
      <child>bogie_left</child>
      <parent>rocker_left</parent>
      <axis>
        <xyz>0 1 0</xyz>
      </axis>
    </joint>

    <joint type="revolute" name="left_bogie_wheel_front">
      <pose>0 0.095 0 0 0 0</pose>
      <child>wheel_left_front</child>
      <parent>bogie_left</parent>
      <axis>
        <xyz>0 1 0</xyz>
      </axis>
    </joint>

    <joint type="revolute" name="left_bogie_wheel_middle">
      <pose>0 0.095 0 0 0 0</pose>
      <child>wheel_left_middle</child>
      <parent>bogie_left</parent>
      <axis>
        <xyz>0 1 0</xyz>
      </axis>
    </joint>
    <joint type="revolute" name="left_bogie_wheel_rear">
      <pose>0 0.095 0 0 0 0</pose>
      <child>wheel_left_rear</child>
      <parent>rocker_left</parent>
      <axis>
        <xyz>0 1 0</xyz>
      </axis>
    </joint>

    <joint type="revolute" name="right_body_rocker">
      <child>rocker_right</child>
      <parent>body</parent>
      <axis>
        <xyz>0 1 0</xyz>
      </axis>
    </joint>

    <joint type="revolute" name="right_rocker_bogie">
      <child>bogie_right</child>
      <parent>rocker_right</parent>
      <axis>
        <xyz>0 1 0</xyz>
        </axis>
    </joint>

    <joint type="revolute" name="right_bogie_wheel_front">
      <pose>0 0.095 0 0 0 0</pose>
      <child>wheel_right_front</child>
      <parent>bogie_right</parent>
      <axis>
        <xyz>0 1 0</xyz>
      </axis>
    </joint>

    <joint type="revolute" name="right_bogie_wheel_middle">
      <pose>0 0.095 0 0 0 0</pose>
      <child>wheel_right_middle</child>
      <parent>bogie_right</parent>
      <axis>
        <xyz>0 1 0</xyz>
      </axis>
    </joint>
    <joint type="revolute" name="right_bogie_wheel_rear">
      <pose>0 0.095 0 0 0 0</pose>
      <child>wheel_right_rear</child>
      <parent>rocker_right</parent>
      <axis>
        <xyz>0 1 0</xyz>
      </axis>
    </joint>

    <!-- Joints for the body balancer. -->
    <joint type="revolute" name="body_hebel">
      <child>hebel</child>
      <parent>body</parent>
      <axis>
        <xyz>0 0 1</xyz>
      </axis>
    </joint>
    <joint type="revolute" name="hebel_verbinder_left">
      <child>verbinder_left</child>
      <parent>hebel</parent>
      <axis>
        <xyz>0 0 1</xyz>
      </axis>
    </joint>
    <joint type="revolute" name="verbinder_rocker_left">
      <child>rocker_left</child>
      <parent>verbinder_left</parent>
      <pose>0 0 0.115 0 0 0</pose>
      <axis>
        <xyz>1 1 1</xyz>
      </axis>
    </joint>
    <joint type="revolute" name="hebel_verbinder_right">
      <child>verbinder_right</child>
      <parent>hebel</parent>
      <axis>
        <xyz>0 0 1</xyz>
      </axis>
    </joint>
    <joint type="revolute" name="verbinder_rocker_right">
      <child>rocker_right</child>
      <parent>verbinder_right</parent>
      <pose>0 0 0.115 0 0 0</pose>
      <axis>
        <xyz>1 1 1</xyz>
      </axis>
    </joint>


<!--    <plugin name="morty_motor_controller" filename="libgazebo_morty_motor_controller.so">

    </plugin>-->
  </model>
</sdf>
