<?xml version='1.0'?>
<sdf version='1.5'>
  <model name="morty">
    <static>false</static>
    <pose>0 0 0.264 0 0 0</pose>

    <link name="body">
      <pose>0 0 0 0 0 0</pose>

      <inertial>
        <pose>-0.010530 0.000000 0.067976 0 0 0</pose>
        <mass>1.0</mass>
        <inertia>
          <ixx>43.604542e-4</ixx>
          <iyy>144.367569e-4</iyy>
          <izz>172.691925e-4</izz>
          <ixz>2.563373e-4
          </ixz>
          <ixy>-0.000009e-4</ixy>
          <iyz>0.0</iyz>
          </inertia>
      </inertial>

      <collision name="collision">
        <pose>0 0 .07 0 0 0</pose>
        <geometry>
          <box>
            <size>.6 .3 .14</size>
          </box>
        </geometry>
      </collision>

      <visual name="visual">
        <geometry>
          <mesh><uri>model://morty/meshes/body.dae</uri></mesh>
        </geometry>
      </visual>
    </link>

    <!-- Left side. -->
    <link name="rocker_left">
      <pose>.0 .168 .046 0 0 1.571</pose>

      <inertial>
        <pose>0.001286 0.014945 -0.056282 0 0 0</pose>
        <mass>1.0</mass>
        <inertia>
          <ixx>2.983909e-2</ixx>
          <iyy>0.652077e-2</iyy>
          <izz>2.346098e-2</izz>
          <ixy>-0.034413e-2</ixy>
          <ixz>0.015052e-2</ixz>
          <iyz>0.420844e-2</iyz>
        </inertia>
      </inertial>

      <collision name="collision_rocker_left">
        <geometry>
          <mesh><uri>model://morty/meshes/rocker_2_left.dae</uri></mesh>
        </geometry>
      </collision>

      <visual name="visual_rocker_left">
        <geometry>
          <mesh><uri>model://morty/meshes/rocker_2_left.dae</uri></mesh>
        </geometry>
      </visual>
    </link>

    <link name="bogie_left">
      <pose>.2 .203 -.067 0 0 0</pose>

      <inertial>
        <pose>0.000632 -0.010000 -0.038800 0 0 0</pose>
        <mass>0.3</mass>
        <inertia>
          <ixx>0.039283e-2</ixx>
          <iyy>0.23786e-2</iyy>
          <izz>0.199871e-2</izz>
          <ixz>0.000113e-2</ixz>
          <ixy>0</ixy>
          <iyz>0</iyz>
        </inertia>
      </inertial>

      <collision name="collision_bogie_left">
        <geometry>
          <mesh>
            <uri>model://morty/meshes/bogie.dae</uri>
          </mesh>
        </geometry>
      </collision>

      <visual name="visual_bogie_left">
        <geometry>
          <mesh>
            <uri>model://morty/meshes/bogie.dae</uri>
          </mesh>
        </geometry>
      </visual>
    </link>

    <link name="wheel_left_front">
      <pose>.35 .287 -.155 3.141592654 0 0</pose>

      <inertial>
        <pose>-0.000000 0.030998 -0.000003 0 0 0</pose>
        <mass>4.0</mass>
        <inertia>
          <ixx>1.835544e-2</ixx>
          <iyy>3.058428e-2</iyy>
          <izz>1.835553e-2</izz>
          <iyz>0.000160e-2</iyz>
          <ixy>0</ixy>
          <ixz>0</ixz>
          </inertia>
      </inertial>

      <collision name="collision_wheel_left_front">
<!--        <pose>0 .03 0 1.570796327 0 0</pose> -->
        <geometry>
<!--          <cylinder>
            <radius>.11</radius>
            <length>.08</length>
          </cylinder>
-->
          <mesh>
<!--            <pose>0 0 0 1.570796327 0 0</pose>-->
            <uri>model://morty/meshes/wheel.dae</uri>
          </mesh>
        </geometry>
        <max_contacts>1</max_contacts>
        <surface>
          <friction>
            <ode>
              <mu>0.5</mu>
              <mu2>0.3</mu2>
              <fdir1>1 0 1</fdir1>
              <fdir2>0 1 0</fdir2>
              <slip1>0.1</slip1>
              <slip2>0.1</slip2>
            </ode>
          </friction>
          <contact>
            <ode>
              <min_depth>0.00</min_depth>
              <max_depth>0.005</max_depth>
              <kp>1e8</kp>
            </ode>
          </contact>
        </surface>
      </collision>
      <collision name="collision_wheel_left_front_axis">
        <pose>0 .11 0 1.570796327 0 0</pose>
        <geometry>
          <cylinder>
            <radius>.01</radius>
            <length>.08</length>
          </cylinder>
        </geometry>
      </collision>

      <visual name="visual_wheel_left_front">
        <geometry>
          <mesh>
            <uri>model://morty/meshes/wheel.dae</uri>
          </mesh>
        </geometry>
      </visual>
    </link>

    <link name="wheel_left_middle">
      <pose>.05 .287 -.155 3.141592654 0 0</pose>

      <inertial>
        <pose>-0.000000 0.030998 -0.000003 0 0 0</pose>
        <mass>4.0</mass>
        <inertia>
          <ixx>1.835544e-2</ixx>
          <iyy>3.058428e-2</iyy>
          <izz>1.835553e-2</izz>
          <iyz>0.000160e-2</iyz>
          <ixy>0</ixy>
          <ixz>0</ixz>
          </inertia>
      </inertial>

      <collision name="collision_wheel_left_middle">
<!--        <pose>0 .03 0 1.570796327 0 0</pose>-->
        <geometry>
<!--
          <cylinder>
            <radius>.11</radius>
            <length>.08</length>
          </cylinder>
-->
          <mesh>
            <uri>model://morty/meshes/wheel.dae</uri>
          </mesh>
        </geometry>
        <max_contacts>1</max_contacts>
        <surface>
          <friction>
            <ode>
              <mu>0.5</mu>
              <mu2>0.3</mu2>
              <fdir1>1 0 1</fdir1>
              <fdir2>0 1 0</fdir2>
              <slip1>0.1</slip1>
              <slip2>0.1</slip2>
            </ode>
          </friction>
          <contact>
            <ode>
              <min_depth>0.00</min_depth>
              <max_depth>0.005</max_depth>
              <kp>1e8</kp>
            </ode>
          </contact>
        </surface>
      </collision>
      <collision name="collision_wheel_left_middle_axis">
        <pose>0 .11 0 1.570796327 0 0</pose>
        <geometry>
          <cylinder>
            <radius>.01</radius>
            <length>.08</length>
          </cylinder>
        </geometry>
      </collision>

      <visual name="visual_wheel_left_middle">
        <geometry>
          <mesh>
            <uri>model://morty/meshes/wheel.dae</uri>
          </mesh>
        </geometry>
      </visual>
    </link>

    <link name="wheel_left_rear">
      <pose>-.35 .287 -.155 3.141592654 0 0</pose>

      <inertial>
        <pose>-0.000000 0.030998 -0.000003 0 0 0</pose>
        <mass>4.0</mass>
        <inertia>
          <ixx>1.835544e-2</ixx>
          <iyy>3.058428e-2</iyy>
          <izz>1.835553e-2</izz>
          <iyz>0.000160e-2</iyz>
          <ixy>0</ixy>
          <ixz>0</ixz>
          </inertia>
      </inertial>

      <collision name="collision_wheel_left_rear">
<!--        <pose>0 .03 0 1.570796327 0 0</pose>-->
        <geometry>
<!--
          <cylinder>
            <radius>.11</radius>
            <length>.08</length>
          </cylinder>
-->
          <mesh>
            <uri>model://morty/meshes/wheel.dae</uri>
          </mesh>
        </geometry>
        <max_contacts>1</max_contacts>
        <surface>
          <friction>
            <ode>
              <mu>0.5</mu>
              <mu2>0.3</mu2>
              <fdir1>1 0 1</fdir1>
              <fdir2>0 1 0</fdir2>
              <slip1>0.1</slip1>
              <slip2>0.1</slip2>
            </ode>
          </friction>
          <contact>
            <ode>
              <min_depth>0.00</min_depth>
              <max_depth>0.005</max_depth>
              <kp>1e8</kp>
            </ode>
          </contact>
        </surface>
      </collision>
      <collision name="collision_wheel_left_rear_axis">
        <pose>0 .11 0 1.570796327 0 0</pose>
        <geometry>
          <cylinder>
            <radius>.01</radius>
            <length>.08</length>
          </cylinder>
        </geometry>
      </collision>

      <visual name="visual_wheel_left_rear">
        <geometry>
          <mesh>
            <uri>model://morty/meshes/wheel.dae</uri>
          </mesh>
        </geometry>
      </visual>
    </link>

    <!-- Right side. -->
    <link name="rocker_right">
      <pose>.0 -.168 .046 0 0 1.570796327</pose>

      <inertial>
        <pose>-0.001461 0.014945 -0.056282 0 0 0</pose>
        <mass>1.0</mass>
        <inertia>
          <ixx>2.983909e-2</ixx>
          <iyy>0.652041e-2</iyy>
          <izz>2.346062e-2</izz>
          <ixy>0.034175e-2</ixy>
          <ixz>-0.014369e-2</ixz>
          <iyz>0.420844e-2</iyz>
        </inertia>
      </inertial>

      <collision name="collision_center">
        <geometry>
          <mesh><uri>model://morty/meshes/rocker_2_right.dae</uri></mesh>
        </geometry>
      </collision>

      <visual name="visual_rocker_right">
        <geometry>
          <mesh><uri>model://morty/meshes/rocker_2_right.dae</uri></mesh>
        </geometry>
      </visual>
    </link>

    <link name="bogie_right">
      <pose>.2 -.183 -.067 0 0 0</pose>

      <inertial>
        <pose>0.000632 -0.010000 -0.038800 0 0 0</pose>
        <mass>0.3</mass>
        <inertia>
          <ixx>0.039283e-2</ixx>
          <iyy>0.23786e-2</iyy>
          <izz>0.199871e-2</izz>
          <ixz>0.000113e-2</ixz>
          <ixy>0</ixy>
          <iyz>0</iyz>
        </inertia>
      </inertial>

      <collision name="collision_bogie_right">
        <geometry>
          <mesh>
            <uri>model://morty/meshes/bogie.dae</uri>
          </mesh>
        </geometry>
      </collision>

      <visual name="visual_bogie_right">
        <geometry>
          <mesh>
            <uri>model://morty/meshes/bogie.dae</uri>
          </mesh>
        </geometry>
      </visual>
    </link>

    <link name="wheel_right_front">
      <pose>.35 -.287 -.155 0 0 0</pose>

      <inertial>
        <pose>-0.000000 0.030998 -0.000003 0 0 0</pose>
        <mass>4.0</mass>
        <inertia>
          <ixx>1.835544e-2</ixx>
          <iyy>3.058428e-2</iyy>
          <izz>1.835553e-2</izz>
          <iyz>0.000160e-2</iyz>
          <ixy>0</ixy>
          <ixz>0</ixz>
          </inertia>
      </inertial>

      <collision name="collision_wheel_right_front">
<!--        <pose>0 .03 0 1.570796327 0 0</pose>-->
        <geometry>
<!--
          <cylinder>
            <radius>.11</radius>
            <length>.08</length>
          </cylinder>
-->
          <mesh>
            <uri>model://morty/meshes/wheel.dae</uri>
          </mesh>
        </geometry>
        <max_contacts>1</max_contacts>
        <surface>
          <friction>
            <ode>
              <mu>0.5</mu>
              <mu2>0.3</mu2>
              <fdir1>1 0 1</fdir1>
              <fdir2>0 1 0</fdir2>
              <slip1>0.1</slip1>
              <slip2>0.1</slip2>
            </ode>
          </friction>
          <contact>
            <ode>
              <min_depth>0.00</min_depth>
              <max_depth>0.005</max_depth>
              <kp>1e8</kp>
            </ode>
          </contact>
        </surface>
      </collision>
      <collision name="collision_wheel_left_right_axis">
        <pose>0 .11 0 1.570796327 0 0</pose>
        <geometry>
          <cylinder>
            <radius>.01</radius>
            <length>.08</length>
          </cylinder>
        </geometry>
      </collision>

      <visual name="visual_wheel_right_front">
        <geometry>
          <mesh>
            <uri>model://morty/meshes/wheel.dae</uri>
          </mesh>
        </geometry>
      </visual>
    </link>

    <link name="wheel_right_middle">
      <pose>.05 -.287 -.155 0 0 0</pose>

      <inertial>
        <pose>-0.000000 0.030998 -0.000003 0 0 0</pose>
        <mass>4.0</mass>
        <inertia>
          <ixx>1.835544e-2</ixx>
          <iyy>3.058428e-2</iyy>
          <izz>1.835553e-2</izz>
          <iyz>0.000160e-2</iyz>
          <ixy>0</ixy>
          <ixz>0</ixz>
          </inertia>
      </inertial>

      <collision name="collision_wheel_right_middle">
<!--        <pose>0 .03 0 1.570796327 0 0</pose>-->
        <geometry>
<!--
          <cylinder>
            <radius>.11</radius>
            <length>.08</length>
          </cylinder>
-->
          <mesh>
            <uri>model://morty/meshes/wheel.dae</uri>
          </mesh>
        </geometry>
        <max_contacts>1</max_contacts>
        <surface>
          <friction>
            <ode>
              <mu>0.5</mu>
              <mu2>0.3</mu2>
              <fdir1>1 0 1</fdir1>
              <fdir2>0 1 0</fdir2>
              <slip1>0.1</slip1>
              <slip2>0.1</slip2>
            </ode>
          </friction>
          <contact>
            <ode>
              <min_depth>0.00</min_depth>
              <max_depth>0.005</max_depth>
              <kp>1e8</kp>
            </ode>
          </contact>
        </surface>
      </collision>
      <collision name="collision_wheel_right_middle_axis">
        <pose>0 .11 0 1.570796327 0 0</pose>
        <geometry>
          <cylinder>
            <radius>.01</radius>
            <length>.08</length>
          </cylinder>
        </geometry>
      </collision>

      <visual name="visual_wheel_right_middle">
        <geometry>
          <mesh>
            <uri>model://morty/meshes/wheel.dae</uri>
          </mesh>
        </geometry>
      </visual>
    </link>

    <link name="wheel_right_rear">
      <pose>-.35 -.287 -.155 0 0 0</pose>

      <inertial>
        <pose>-0.000000 0.030998 -0.000003 0 0 0</pose>
        <mass>4.0</mass>
        <inertia>
          <ixx>1.835544e-2</ixx>
          <iyy>3.058428e-2</iyy>
          <izz>1.835553e-2</izz>
          <iyz>0.000160e-2</iyz>
          <ixy>0</ixy>
          <ixz>0</ixz>
          </inertia>
      </inertial>

      <collision name="collision_wheel_right_rear">
<!--        <pose>0 .03 0 1.570796327 0 0</pose>-->
        <geometry>
<!--
          <cylinder>
            <radius>.11</radius>
            <length>.08</length>
          </cylinder>
-->
          <mesh>
            <uri>model://morty/meshes/wheel.dae</uri>
          </mesh>
        </geometry>
        <max_contacts>1</max_contacts>
        <surface>
          <friction>
            <ode>
              <mu>0.5</mu>
              <mu2>0.3</mu2>
              <fdir1>1 0 1</fdir1>
              <fdir2>0 1 0</fdir2>
              <slip1>0.1</slip1>
              <slip2>0.1</slip2>
            </ode>
          </friction>
          <contact>
            <ode>
              <min_depth>0.00</min_depth>
              <max_depth>0.005</max_depth>
              <kp>1e8</kp>
            </ode>
          </contact>
        </surface>
      </collision>
      <collision name="collision_wheel_right_rear_axis">
        <pose>0 .11 0 1.570796327 0 0</pose>
        <geometry>
          <cylinder>
            <radius>.01</radius>
            <length>.08</length>
          </cylinder>
        </geometry>
      </collision>

      <visual name="visual_wheel_right_rear">
        <geometry>
          <mesh>
            <uri>model://morty/meshes/wheel.dae</uri>
          </mesh>
        </geometry>
      </visual>
    </link>

    <!-- Hebel -->
    <link name="hebel">
      <pose>-0.153 0 0.14 0 0 0</pose>

      <inertial>
        <pose>0.000000 -0.000000 0.010000 0 0 0</pose>
        <mass>2.0</mass>
        <inertia>
          <ixx>0.204804e-1</ixx>
          <iyy>0.006227e-1</iyy>
          <izz>0.209905e-1</izz>
          <ixy>0</ixy>
          <ixz>0</ixz>
          <iyz>0</iyz>
        </inertia>
      </inertial>
      <collision name="collision_hebel">
        <geometry>
          <mesh>
            <uri>model://morty/meshes/hebel.dae</uri>
          </mesh>
        </geometry>
      </collision>

      <visual name="visual_hebel">
        <geometry>
          <mesh>
            <uri>model://morty/meshes/hebel.dae</uri>
          </mesh>
        </geometry>
      </visual>
    </link>

    <link name="verbinder_left">
      <pose>-0.153 0.167 0.15 0 -0.06981317 0</pose>

      <inertial>
        <pose>0.050000 0.000455 0.006981 0 0 0</pose>
        <mass>0.3</mass>
        <inertia>
          <ixx>0.000413e-1</ixx>
          <iyy>0.008758e-1</iyy>
          <izz>0.008759e-1</izz>
          <ixy>0.000063e-1</ixy>
          <ixz>-0.000032e-1</ixz>
          <iyz>0.000024e-1</iyz>
        </inertia>
      </inertial>

      <collision name="collision_verbinder_left">
        <geometry>
          <mesh>
            <uri>model://morty/meshes/verbinder.dae</uri>
          </mesh>
        </geometry>
      </collision>

      <visual name="visual_verbinder_left">
        <geometry>
          <mesh>
            <uri>model://morty/meshes/verbinder.dae</uri>
          </mesh>
        </geometry>
      </visual>
    </link>

    <link name="verbinder_right">
      <pose>-0.153 -0.167 0.15 0 -0.06981317 0</pose>

      <inertial>
        <pose>0.050000 0.000455 0.006981 0 0 0</pose>
        <mass>0.3</mass>
        <inertia>
          <ixx>0.000413e-1</ixx>
          <iyy>0.008758e-1</iyy>
          <izz>0.008759e-1</izz>
          <ixy>0.000063e-1</ixy>
          <ixz>-0.000032e-1</ixz>
          <iyz>0.000024e-1</iyz>
        </inertia>
      </inertial>

      <collision name="collision">
        <geometry>
          <mesh>
            <uri>model://morty/meshes/verbinder.dae</uri>
          </mesh>
        </geometry>
      </collision>

      <visual name="visual">
        <geometry>
          <mesh>
            <uri>model://morty/meshes/verbinder.dae</uri>
          </mesh>
        </geometry>
      </visual>
    </link>

    <!-- Sensors -->
    <include>
      <uri>model://laser_leveling</uri>
      <pose>0.2 0.0 0.14 0 0 0</pose>
    </include>
    <include>
      <uri>model://rplidar_a2_m6</uri>
      <pose>0.222 0.0 0.22 0 0 0</pose>
      <parent>laser_leveling</parent>
    </include>

    <!-- Joints -->
    <!-- Joints left. -->
    <joint type="revolute" name="left_body_rocker">
      <pose>-0.01 0 0 0 0 0</pose>
      <child>rocker_left</child>
      <parent>body</parent>
      <axis>
        <xyz>1 0 0</xyz>
      </axis>
    </joint>

    <joint type="revolute" name="left_rocker_bogie">
      <pose>0 -0.02 0 0 0 0</pose>
      <child>bogie_left</child>
      <parent>rocker_left</parent>
      <axis>
        <xyz>0 1 0</xyz>
        <limit>
          <lower>-1.570796327</lower>
          <upper>1.570796327</upper>
        </limit>
      </axis>
    </joint>

    <joint type="revolute" name="left_bogie_wheel_front">
      <pose>0 0.095 0 0 0 3.141592654</pose>
      <child>wheel_left_front</child>
      <parent>bogie_left</parent>
      <axis>
        <xyz>0 1 0</xyz>
      </axis>
    </joint>

    <joint type="revolute" name="left_bogie_wheel_middle">
      <pose>0 0.095 0 0 0 3.141592654</pose>
      <child>wheel_left_middle</child>
      <parent>bogie_left</parent>
      <axis>
        <xyz>0 1 0</xyz>
      </axis>
    </joint>
    <joint type="revolute" name="left_rocker_wheel_rear">
      <pose>0 0.095 0 0 0 3.141592654</pose>
      <child>wheel_left_rear</child>
      <parent>rocker_left</parent>
      <axis>
        <xyz>0 1 0</xyz>
      </axis>
    </joint>

    <!-- Joints right. -->
    <joint type="revolute" name="right_body_rocker">
      <pose>0.01 0 0 0 0 0</pose>
      <child>rocker_right</child>
      <parent>body</parent>
      <axis>
        <xyz>1 0 0</xyz>
      </axis>
    </joint>

    <joint type="revolute" name="right_rocker_bogie">
      <child>bogie_right</child>
      <parent>rocker_right</parent>
      <axis>
        <xyz>0 1 0</xyz>
        <limit>
          <lower>-1.570796327</lower>
          <upper>1.570796327</upper>
        </limit>
      </axis>
    </joint>

    <joint type="revolute" name="right_bogie_wheel_front">
      <pose>0 0.095 0 0 0 0</pose>
      <child>wheel_right_front</child>
      <parent>bogie_right</parent>
      <axis>
        <xyz>0 1 0</xyz>
      </axis>
    </joint>

    <joint type="revolute" name="right_bogie_wheel_middle">
      <pose>0 0.095 0 0 0 0</pose>
      <child>wheel_right_middle</child>
      <parent>bogie_right</parent>
      <axis>
        <xyz>0 1 0</xyz>
      </axis>
    </joint>
    <joint type="revolute" name="right_rocker_wheel_rear">
      <pose>0 0.095 0 0 0 0</pose>
      <child>wheel_right_rear</child>
      <parent>rocker_right</parent>
      <axis>
        <xyz>0 1 0</xyz>
      </axis>
    </joint>

    <!-- Joints for the body balancer. -->
    <joint type="revolute" name="body_hebel">
      <child>hebel</child>
      <parent>body</parent>
      <axis>
        <xyz>0 0 1</xyz>
      </axis>
    </joint>
    <joint type="ball" name="hebel_verbinder_left">
      <child>verbinder_left</child>
      <parent>hebel</parent>
      <axis>
        <dynamics>
          <friction>0.1</friction>
        </dynamics>
      </axis>
    </joint>
    <joint type="ball" name="verbinder_rocker_left">
      <child>rocker_left</child>
      <parent>verbinder_left</parent>
      <pose>0 0 0.115 0 0 0</pose>
      <axis>
        <dynamics>
          <friction>0.1</friction>
        </dynamics>
      </axis>
    </joint>
    <joint type="ball" name="hebel_verbinder_right">
      <child>verbinder_right</child>
      <parent>hebel</parent>
      <axis>
        <dynamics>
          <friction>0.1</friction>
        </dynamics>
      </axis>
    </joint>
    <joint type="ball" name="verbinder_rocker_right">
      <child>rocker_right</child>
      <parent>verbinder_right</parent>
      <pose>0 0 0.115 0 0 0</pose>
      <axis>
        <dynamics>
          <friction>0.1</friction>
        </dynamics>
      </axis>
    </joint>

    <!-- Joints for the sensors. -->
    <joint type="fixed" name="mount_leveling">
      <child>laser_leveling::dynamixel_roll</child>
      <parent>body</parent>
    </joint>
    <joint type="fixed" name="laser_leveling">
      <child>rplidar_a2_m6::case</child>
      <parent>laser_leveling::mount_dynamixel_pitch</parent>
    </joint>

    <plugin name="morty_motor_controller" filename="libgazebo-francor-morty-motor-controller-plugin.so">
      <motorLeftFrontJoint>left_bogie_wheel_front</motorLeftFrontJoint>
      <motorLeftMidJoint>left_bogie_wheel_middle</motorLeftMidJoint>
      <motorLeftRearJoint>left_rocker_wheel_rear</motorLeftRearJoint>
      <motorRightFrontJoint>right_bogie_wheel_front</motorRightFrontJoint>
      <motorRightMidJoint>right_bogie_wheel_middle</motorRightMidJoint>
      <motorRightRearJoint>right_rocker_wheel_rear</motorRightRearJoint>

      <motorLeftFrontPos>0.35 0.24 0</motorLeftFrontPos>
      <motorLeftMidPos>0.05 0.24 0</motorLeftMidPos>
      <motorLeftRearPos>-0.35 0.24 0</motorLeftRearPos>
      <motorRightFrontPos>0.35 -0.24 0</motorRightFrontPos>
      <motorRightMidPos>0.25 -0.24 0</motorRightMidPos>
      <motorRightRearPos>0.25 -0.24 0</motorRightRearPos>

      <motorLeftFrontDiameter>0.22</motorLeftFrontDiameter>
      <motorLeftMidDiameter>0.22</motorLeftMidDiameter>
      <motorLeftRearDiameter>0.22</motorLeftRearDiameter>
      <motorRightFrontDiameter>0.22</motorRightFrontDiameter>
      <motorRightMidDiameter>0.22</motorRightMidDiameter>
      <motorRightRearDiameter>0.22</motorRightRearDiameter>

      <rosNamespace>morty</rosNamespace>
      <velocityTopic>velocity</velocityTopic>
      <odometryTopic>odom</odometryTopic>
    </plugin>
  </model>
</sdf>
